2025-08-05 18:52:25,775 - ERROR TRACKING FALLBACK - Failed to record error in analytics: cannot import name 'get_db_connection' from 'utils.database' (/home/retiredfan/Documents/github/linux_plus_study_v3_main/linux_plus_study_v3/utils/database.py)
2025-08-05 18:52:25,775 - ERROR TRACKING FALLBACK - Original error details: {'error_type': 'database_error', 'error_message': 'Database session error: Column expression, FROM clause, or other columns clause element expected, got <sqlalchemy.orm.session.Session object at 0x7aef92da0b90>.', 'timestamp': '2025-08-05T23:52:25.774739+00:00', 'request_url': 'http://127.0.0.1:5000/api/analytics/errors', 'request_method': 'GET', 'user_id': None, 'session_id': 'c60e2a32-b652-49b8-9a82-701bfad3f1a4', 'sql_query': 'unknown', 'sql_parameters': None, 'database_type': 'sqlite'}
2025-08-05 18:52:25,775 - ERROR TRACKING FALLBACK - STRUCTURED_ERROR: {"event_type": "error_tracked", "error_details": {"error_type": "database_error", "error_message": "Database session error: Column expression, FROM clause, or other columns clause element expected, got <sqlalchemy.orm.session.Session object at 0x7aef92da0b90>.", "timestamp": "2025-08-05T23:52:25.774739+00:00", "request_url": "http://127.0.0.1:5000/api/analytics/errors", "request_method": "GET", "user_id": null, "session_id": "c60e2a32-b652-49b8-9a82-701bfad3f1a4", "sql_query": "unknown", "sql_parameters": null, "database_type": "sqlite"}, "environment": {"python_version": "3.12.3 (main, Jun 18 2025, 17:59:45) [GCC 13.3.0]", "platform": "posix"}}
2025-08-05 18:52:25,775 - ERROR TRACKING FALLBACK - Failed to record error in analytics: cannot import name 'get_db_connection' from 'utils.database' (/home/retiredfan/Documents/github/linux_plus_study_v3_main/linux_plus_study_v3/utils/database.py)
2025-08-05 18:52:25,775 - ERROR TRACKING FALLBACK - Original error details: {'error_type': 'database_error', 'error_message': 'Database session error: Column expression, FROM clause, or other columns clause element expected, got <sqlalchemy.orm.session.Session object at 0x7aef92da0b90>.', 'timestamp': '2025-08-05T23:52:25.775553+00:00', 'request_url': 'http://127.0.0.1:5000/api/analytics/errors', 'request_method': 'GET', 'user_id': None, 'session_id': 'c60e2a32-b652-49b8-9a82-701bfad3f1a4', 'logger_name': 'utils.database', 'log_level': 'ERROR', 'module': 'database', 'function': 'get_session'}
2025-08-05 18:52:25,775 - ERROR TRACKING FALLBACK - STRUCTURED_ERROR: {"event_type": "error_tracked", "error_details": {"error_type": "database_error", "error_message": "Database session error: Column expression, FROM clause, or other columns clause element expected, got <sqlalchemy.orm.session.Session object at 0x7aef92da0b90>.", "timestamp": "2025-08-05T23:52:25.775553+00:00", "request_url": "http://127.0.0.1:5000/api/analytics/errors", "request_method": "GET", "user_id": null, "session_id": "c60e2a32-b652-49b8-9a82-701bfad3f1a4", "logger_name": "utils.database", "log_level": "ERROR", "module": "database", "function": "get_session"}, "environment": {"python_version": "3.12.3 (main, Jun 18 2025, 17:59:45) [GCC 13.3.0]", "platform": "posix"}}
2025-08-05 18:52:25,774 - ERROR TRACKING FALLBACK - Database session error: Column expression, FROM clause, or other columns clause element expected, got <sqlalchemy.orm.session.Session object at 0x7aef92da0b90>.
2025-08-05 18:52:25,776 - ERROR TRACKING FALLBACK - 127.0.0.1 - - [05/Aug/2025 18:52:25] "GET /api/analytics/errors HTTP/1.1" 200 -
2025-08-05 18:52:25,781 - ERROR TRACKING FALLBACK - All database connections closed
2025-08-05 18:55:19,913 - ERROR TRACKING FALLBACK - Failed to record error in analytics: cannot import name 'get_db_connection' from 'utils.database' (/home/retiredfan/Documents/github/linux_plus_study_v3_main/linux_plus_study_v3/utils/database.py)
2025-08-05 18:55:19,913 - ERROR TRACKING FALLBACK - Original error details: {'error_type': 'database_error', 'error_message': 'Database session error: Column expression, FROM clause, or other columns clause element expected, got <sqlalchemy.orm.session.Session object at 0x7213c2daa3c0>.', 'timestamp': '2025-08-05T23:55:19.912810+00:00', 'request_url': 'http://127.0.0.1:5001/api/analytics/errors', 'request_method': 'GET', 'user_id': None, 'session_id': 'f925c400-0c45-47e9-bb5f-ca0f092aed66', 'sql_query': 'unknown', 'sql_parameters': None, 'database_type': 'sqlite'}
2025-08-05 18:55:19,913 - ERROR TRACKING FALLBACK - STRUCTURED_ERROR: {"event_type": "error_tracked", "error_details": {"error_type": "database_error", "error_message": "Database session error: Column expression, FROM clause, or other columns clause element expected, got <sqlalchemy.orm.session.Session object at 0x7213c2daa3c0>.", "timestamp": "2025-08-05T23:55:19.912810+00:00", "request_url": "http://127.0.0.1:5001/api/analytics/errors", "request_method": "GET", "user_id": null, "session_id": "f925c400-0c45-47e9-bb5f-ca0f092aed66", "sql_query": "unknown", "sql_parameters": null, "database_type": "sqlite"}, "environment": {"python_version": "3.12.3 (main, Jun 18 2025, 17:59:45) [GCC 13.3.0]", "platform": "posix"}}
2025-08-05 18:55:19,913 - ERROR TRACKING FALLBACK - Failed to record error in analytics: cannot import name 'get_db_connection' from 'utils.database' (/home/retiredfan/Documents/github/linux_plus_study_v3_main/linux_plus_study_v3/utils/database.py)
2025-08-05 18:55:19,913 - ERROR TRACKING FALLBACK - Original error details: {'error_type': 'database_error', 'error_message': 'Database session error: Column expression, FROM clause, or other columns clause element expected, got <sqlalchemy.orm.session.Session object at 0x7213c2daa3c0>.', 'timestamp': '2025-08-05T23:55:19.913232+00:00', 'request_url': 'http://127.0.0.1:5001/api/analytics/errors', 'request_method': 'GET', 'user_id': None, 'session_id': 'f925c400-0c45-47e9-bb5f-ca0f092aed66', 'logger_name': 'utils.database', 'log_level': 'ERROR', 'module': 'database', 'function': 'get_session'}
2025-08-05 18:55:19,913 - ERROR TRACKING FALLBACK - STRUCTURED_ERROR: {"event_type": "error_tracked", "error_details": {"error_type": "database_error", "error_message": "Database session error: Column expression, FROM clause, or other columns clause element expected, got <sqlalchemy.orm.session.Session object at 0x7213c2daa3c0>.", "timestamp": "2025-08-05T23:55:19.913232+00:00", "request_url": "http://127.0.0.1:5001/api/analytics/errors", "request_method": "GET", "user_id": null, "session_id": "f925c400-0c45-47e9-bb5f-ca0f092aed66", "logger_name": "utils.database", "log_level": "ERROR", "module": "database", "function": "get_session"}, "environment": {"python_version": "3.12.3 (main, Jun 18 2025, 17:59:45) [GCC 13.3.0]", "platform": "posix"}}
2025-08-05 18:55:19,912 - ERROR TRACKING FALLBACK - Database session error: Column expression, FROM clause, or other columns clause element expected, got <sqlalchemy.orm.session.Session object at 0x7213c2daa3c0>.
2025-08-05 18:55:19,913 - ERROR TRACKING FALLBACK - 127.0.0.1 - - [05/Aug/2025 18:55:19] "GET /api/analytics/errors HTTP/1.1" 200 -
2025-08-05 18:55:19,914 - ERROR TRACKING FALLBACK - All database connections closed
2025-08-05 21:44:12,763 - ERROR TRACKING FALLBACK - Failed to record error in analytics: NOT NULL constraint failed: analytics.content_pages_viewed
2025-08-05 21:44:12,763 - ERROR TRACKING FALLBACK - Original error details: {'error_type': 'flask_test_error', 'error_message': 'Test error from Flask application context', 'timestamp': '2025-08-06T02:44:12.762866+00:00', 'request_url': None, 'request_method': None, 'user_id': None, 'session_id': None, 'source': 'flask_test', 'user_agent': 'test_browser'}
2025-08-05 21:44:12,763 - ERROR TRACKING FALLBACK - STRUCTURED_ERROR: {"event_type": "error_tracked", "error_details": {"error_type": "flask_test_error", "error_message": "Test error from Flask application context", "timestamp": "2025-08-06T02:44:12.762866+00:00", "request_url": null, "request_method": null, "user_id": null, "session_id": null, "source": "flask_test", "user_agent": "test_browser"}, "environment": {"python_version": "3.12.3 (main, Jun 18 2025, 17:59:45) [GCC 13.3.0]", "platform": "posix"}}
2025-08-05 21:44:12,763 - ERROR TRACKING FALLBACK - All database connections closed
2025-08-05 21:45:16,337 - ERROR TRACKING FALLBACK - Failed to record error in analytics: NOT NULL constraint failed: analytics.content_pages_viewed
2025-08-05 21:45:16,337 - ERROR TRACKING FALLBACK - Original error details: {'error_type': 'flask_test_error', 'error_message': 'Test error from Flask application context', 'timestamp': '2025-08-06T02:45:16.335681+00:00', 'request_url': None, 'request_method': None, 'user_id': None, 'session_id': None, 'source': 'flask_test', 'user_agent': 'test_browser'}
2025-08-05 21:45:16,337 - ERROR TRACKING FALLBACK - STRUCTURED_ERROR: {"event_type": "error_tracked", "error_details": {"error_type": "flask_test_error", "error_message": "Test error from Flask application context", "timestamp": "2025-08-06T02:45:16.335681+00:00", "request_url": null, "request_method": null, "user_id": null, "session_id": null, "source": "flask_test", "user_agent": "test_browser"}, "environment": {"python_version": "3.12.3 (main, Jun 18 2025, 17:59:45) [GCC 13.3.0]", "platform": "posix"}}
2025-08-05 21:45:16,338 - ERROR TRACKING FALLBACK - All database connections closed
